{
  "cells": [
    {
      "cell_type": "markdown",
      "source": [
        "# Azure Machine Learningでノートブックを始める\n",
        "\n",
        "Azure Machine Learningは機械学習を作成・管理するためのクラウドサービスで、  \n",
        "データサイエンスや機械学習の作業の多くは、このようなノートブックで実現できる。\n",
        "\n",
        "## Azure ML Python SDK\n",
        "\n",
        "このケースでは、Azure MLコンピューティングインスタンス上のConda環境でノートブックを実行している。  \n",
        "この環境はデフォルトでコンピューティングインスタンスにPythonパッケージがインストールされており、  \n",
        "データサイエンティストが通常使用する一般的なPythonパッケージが含まれている。\n",
        "\n",
        "また、Azure ML Python SDKも含まれており、これはAzure MLワークスペースのリソースを使用するコードを書くことができるPythonパッケージである。\n",
        "\n",
        "以下のセルを実行して、`azureml-core`パッケージをインポートし、インストールされているSDKのバージョンを確認する。"
      ],
      "metadata": {}
    },
    {
      "cell_type": "code",
      "source": [
        "import azureml.core\n",
        "\n",
        "print(\"Ready to use Azure ML\", azureml.core.VERSION)"
      ],
      "outputs": [
        {
          "output_type": "stream",
          "name": "stdout",
          "text": [
            "Ready to use Azure ML 1.28.0\n",
            "ERROR! Session/line number was not unique in database. History logging moved to new session 4\n"
          ]
        }
      ],
      "execution_count": 4,
      "metadata": {
        "gather": {
          "logged": 1623578679571
        }
      }
    },
    {
      "cell_type": "markdown",
      "source": [
        "## ワークスペースの接続\n",
        "\n",
        "すべての実験と関連するリソースは、Azure MLのワークスペース内で管理される。  \n",
        "既存のワークスペースに接続するか、Azure ML SDKを使用して新しいワークスペースを作成することができる。\n",
        "\n",
        "ほとんどの場合、ワークスペースの接続情報JSONファイルに保存する必要がある。\n",
        "これにより、AzureのサブスクリプションIDなどの詳細を覚えておく必要がなく、簡単に接続することができる。\n",
        "\n",
        "JSONファイルは、Azureポータルのワークスペース用ブレード、またはAzure MLスタジオのワークスペース詳細ペインからダウンロードできるが、  \n",
        "ワークスペース内でコンピューティングインスタンスを使用している場合は、構成ファイルはすでにルートフォルダにダウンロードされている。\n",
        "\n",
        "以下のコードは、設定ファイルを使用してワークスペースに接続している。  \n",
        "> 注:ノーツブックセッションでワークスペースに初めて接続した時、Azureにサインインするように促されることがある。  \n",
        "サインインに成功したら、開いていたブラウザタブを閉じ、このノートブックに戻ることができる。"
      ],
      "metadata": {}
    },
    {
      "cell_type": "code",
      "source": [
        "from azureml.core import Workspace\n",
        "\n",
        "ws = Workspace.from_config()\n",
        "print(ws.name, \"loaded\")"
      ],
      "outputs": [
        {
          "output_type": "stream",
          "name": "stderr",
          "text": [
            "ERROR:root:Internal Python error in the inspect module.\n",
            "Below is the traceback from this internal error.\n",
            "\n",
            "ERROR:root:Internal Python error in the inspect module.\n",
            "Below is the traceback from this internal error.\n",
            "\n",
            "ERROR:root:Internal Python error in the inspect module.\n",
            "Below is the traceback from this internal error.\n",
            "\n"
          ]
        },
        {
          "output_type": "stream",
          "name": "stdout",
          "text": [
            "Traceback (most recent call last):\n",
            "  File \"/anaconda/envs/azureml_py36/lib/python3.6/site-packages/IPython/core/interactiveshell.py\", line 3343, in run_code\n",
            "    exec(code_obj, self.user_global_ns, self.user_ns)\n",
            "  File \"<ipython-input-4-ce2cb670ba23>\", line 3, in <module>\n",
            "    ws = Workspace.from_config()\n",
            "  File \"/anaconda/envs/azureml_py36/lib/python3.6/site-packages/azureml/core/workspace.py\", line 246, in from_config\n",
            "    normalized_path = normalize_path(path)\n",
            "  File \"/anaconda/envs/azureml_py36/lib/python3.6/site-packages/azureml/_file_utils/file_utils.py\", line 54, in normalize_path\n",
            "    return os.path.abspath(os.path.expanduser(path))\n",
            "  File \"/anaconda/envs/azureml_py36/lib/python3.6/posixpath.py\", line 383, in abspath\n",
            "    cwd = os.getcwd()\n",
            "FileNotFoundError: [Errno 2] No such file or directory\n",
            "\n",
            "During handling of the above exception, another exception occurred:\n",
            "\n",
            "Traceback (most recent call last):\n",
            "  File \"/anaconda/envs/azureml_py36/lib/python3.6/site-packages/IPython/core/interactiveshell.py\", line 2044, in showtraceback\n",
            "    stb = value._render_traceback_()\n",
            "AttributeError: 'FileNotFoundError' object has no attribute '_render_traceback_'\n",
            "\n",
            "During handling of the above exception, another exception occurred:\n",
            "\n",
            "Traceback (most recent call last):\n",
            "  File \"/anaconda/envs/azureml_py36/lib/python3.6/site-packages/IPython/core/ultratb.py\", line 1169, in get_records\n",
            "    return _fixed_getinnerframes(etb, number_of_lines_of_context, tb_offset)\n",
            "  File \"/anaconda/envs/azureml_py36/lib/python3.6/site-packages/IPython/core/ultratb.py\", line 316, in wrapped\n",
            "    return f(*args, **kwargs)\n",
            "  File \"/anaconda/envs/azureml_py36/lib/python3.6/site-packages/IPython/core/ultratb.py\", line 350, in _fixed_getinnerframes\n",
            "    records = fix_frame_records_filenames(inspect.getinnerframes(etb, context))\n",
            "  File \"/anaconda/envs/azureml_py36/lib/python3.6/inspect.py\", line 1490, in getinnerframes\n",
            "    frameinfo = (tb.tb_frame,) + getframeinfo(tb, context)\n",
            "  File \"/anaconda/envs/azureml_py36/lib/python3.6/inspect.py\", line 1448, in getframeinfo\n",
            "    filename = getsourcefile(frame) or getfile(frame)\n",
            "  File \"/anaconda/envs/azureml_py36/lib/python3.6/inspect.py\", line 696, in getsourcefile\n",
            "    if getattr(getmodule(object, filename), '__loader__', None) is not None:\n",
            "  File \"/anaconda/envs/azureml_py36/lib/python3.6/inspect.py\", line 725, in getmodule\n",
            "    file = getabsfile(object, _filename)\n",
            "  File \"/anaconda/envs/azureml_py36/lib/python3.6/inspect.py\", line 709, in getabsfile\n",
            "    return os.path.normcase(os.path.abspath(_filename))\n",
            "  File \"/anaconda/envs/azureml_py36/lib/python3.6/posixpath.py\", line 383, in abspath\n",
            "    cwd = os.getcwd()\n",
            "FileNotFoundError: [Errno 2] No such file or directory\n",
            "Traceback (most recent call last):\n",
            "  File \"/anaconda/envs/azureml_py36/lib/python3.6/site-packages/IPython/core/interactiveshell.py\", line 3343, in run_code\n",
            "    exec(code_obj, self.user_global_ns, self.user_ns)\n",
            "  File \"<ipython-input-4-ce2cb670ba23>\", line 3, in <module>\n",
            "    ws = Workspace.from_config()\n",
            "  File \"/anaconda/envs/azureml_py36/lib/python3.6/site-packages/azureml/core/workspace.py\", line 246, in from_config\n",
            "    normalized_path = normalize_path(path)\n",
            "  File \"/anaconda/envs/azureml_py36/lib/python3.6/site-packages/azureml/_file_utils/file_utils.py\", line 54, in normalize_path\n",
            "    return os.path.abspath(os.path.expanduser(path))\n",
            "  File \"/anaconda/envs/azureml_py36/lib/python3.6/posixpath.py\", line 383, in abspath\n",
            "    cwd = os.getcwd()\n",
            "FileNotFoundError: [Errno 2] No such file or directory\n",
            "\n",
            "During handling of the above exception, another exception occurred:\n",
            "\n",
            "Traceback (most recent call last):\n",
            "  File \"/anaconda/envs/azureml_py36/lib/python3.6/site-packages/IPython/core/interactiveshell.py\", line 2044, in showtraceback\n",
            "    stb = value._render_traceback_()\n",
            "AttributeError: 'FileNotFoundError' object has no attribute '_render_traceback_'\n",
            "\n",
            "During handling of the above exception, another exception occurred:\n",
            "\n",
            "Traceback (most recent call last):\n",
            "  File \"/anaconda/envs/azureml_py36/lib/python3.6/site-packages/IPython/core/interactiveshell.py\", line 3263, in run_ast_nodes\n",
            "    if (await self.run_code(code, result,  async_=asy)):\n",
            "  File \"/anaconda/envs/azureml_py36/lib/python3.6/site-packages/IPython/core/interactiveshell.py\", line 3360, in run_code\n",
            "    self.showtraceback(running_compiled_code=True)\n",
            "  File \"/anaconda/envs/azureml_py36/lib/python3.6/site-packages/IPython/core/interactiveshell.py\", line 2047, in showtraceback\n",
            "    value, tb, tb_offset=tb_offset)\n",
            "  File \"/anaconda/envs/azureml_py36/lib/python3.6/site-packages/IPython/core/ultratb.py\", line 1436, in structured_traceback\n",
            "    self, etype, value, tb, tb_offset, number_of_lines_of_context)\n",
            "  File \"/anaconda/envs/azureml_py36/lib/python3.6/site-packages/IPython/core/ultratb.py\", line 1336, in structured_traceback\n",
            "    self, etype, value, tb, tb_offset, number_of_lines_of_context\n",
            "  File \"/anaconda/envs/azureml_py36/lib/python3.6/site-packages/IPython/core/ultratb.py\", line 1193, in structured_traceback\n",
            "    tb_offset)\n",
            "  File \"/anaconda/envs/azureml_py36/lib/python3.6/site-packages/IPython/core/ultratb.py\", line 1150, in format_exception_as_a_whole\n",
            "    last_unique, recursion_repeat = find_recursion(orig_etype, evalue, records)\n",
            "  File \"/anaconda/envs/azureml_py36/lib/python3.6/site-packages/IPython/core/ultratb.py\", line 451, in find_recursion\n",
            "    return len(records), 0\n",
            "TypeError: object of type 'NoneType' has no len()\n",
            "\n",
            "During handling of the above exception, another exception occurred:\n",
            "\n",
            "Traceback (most recent call last):\n",
            "  File \"/anaconda/envs/azureml_py36/lib/python3.6/site-packages/IPython/core/interactiveshell.py\", line 2044, in showtraceback\n",
            "    stb = value._render_traceback_()\n",
            "AttributeError: 'TypeError' object has no attribute '_render_traceback_'\n",
            "\n",
            "During handling of the above exception, another exception occurred:\n",
            "\n",
            "Traceback (most recent call last):\n",
            "  File \"/anaconda/envs/azureml_py36/lib/python3.6/site-packages/IPython/core/ultratb.py\", line 1169, in get_records\n",
            "    return _fixed_getinnerframes(etb, number_of_lines_of_context, tb_offset)\n",
            "  File \"/anaconda/envs/azureml_py36/lib/python3.6/site-packages/IPython/core/ultratb.py\", line 316, in wrapped\n",
            "    return f(*args, **kwargs)\n",
            "  File \"/anaconda/envs/azureml_py36/lib/python3.6/site-packages/IPython/core/ultratb.py\", line 350, in _fixed_getinnerframes\n",
            "    records = fix_frame_records_filenames(inspect.getinnerframes(etb, context))\n",
            "  File \"/anaconda/envs/azureml_py36/lib/python3.6/inspect.py\", line 1490, in getinnerframes\n",
            "    frameinfo = (tb.tb_frame,) + getframeinfo(tb, context)\n",
            "  File \"/anaconda/envs/azureml_py36/lib/python3.6/inspect.py\", line 1448, in getframeinfo\n",
            "    filename = getsourcefile(frame) or getfile(frame)\n",
            "  File \"/anaconda/envs/azureml_py36/lib/python3.6/inspect.py\", line 696, in getsourcefile\n",
            "    if getattr(getmodule(object, filename), '__loader__', None) is not None:\n",
            "  File \"/anaconda/envs/azureml_py36/lib/python3.6/inspect.py\", line 725, in getmodule\n",
            "    file = getabsfile(object, _filename)\n",
            "  File \"/anaconda/envs/azureml_py36/lib/python3.6/inspect.py\", line 709, in getabsfile\n",
            "    return os.path.normcase(os.path.abspath(_filename))\n",
            "  File \"/anaconda/envs/azureml_py36/lib/python3.6/posixpath.py\", line 383, in abspath\n",
            "    cwd = os.getcwd()\n",
            "FileNotFoundError: [Errno 2] No such file or directory\n",
            "Traceback (most recent call last):\n",
            "  File \"/anaconda/envs/azureml_py36/lib/python3.6/site-packages/IPython/core/interactiveshell.py\", line 3343, in run_code\n",
            "    exec(code_obj, self.user_global_ns, self.user_ns)\n",
            "  File \"<ipython-input-4-ce2cb670ba23>\", line 3, in <module>\n",
            "    ws = Workspace.from_config()\n",
            "  File \"/anaconda/envs/azureml_py36/lib/python3.6/site-packages/azureml/core/workspace.py\", line 246, in from_config\n",
            "    normalized_path = normalize_path(path)\n",
            "  File \"/anaconda/envs/azureml_py36/lib/python3.6/site-packages/azureml/_file_utils/file_utils.py\", line 54, in normalize_path\n",
            "    return os.path.abspath(os.path.expanduser(path))\n",
            "  File \"/anaconda/envs/azureml_py36/lib/python3.6/posixpath.py\", line 383, in abspath\n",
            "    cwd = os.getcwd()\n",
            "FileNotFoundError: [Errno 2] No such file or directory\n",
            "\n",
            "During handling of the above exception, another exception occurred:\n",
            "\n",
            "Traceback (most recent call last):\n",
            "  File \"/anaconda/envs/azureml_py36/lib/python3.6/site-packages/IPython/core/interactiveshell.py\", line 2044, in showtraceback\n",
            "    stb = value._render_traceback_()\n",
            "AttributeError: 'FileNotFoundError' object has no attribute '_render_traceback_'\n",
            "\n",
            "During handling of the above exception, another exception occurred:\n",
            "\n",
            "Traceback (most recent call last):\n",
            "  File \"/anaconda/envs/azureml_py36/lib/python3.6/site-packages/IPython/core/interactiveshell.py\", line 3263, in run_ast_nodes\n",
            "    if (await self.run_code(code, result,  async_=asy)):\n",
            "  File \"/anaconda/envs/azureml_py36/lib/python3.6/site-packages/IPython/core/interactiveshell.py\", line 3360, in run_code\n",
            "    self.showtraceback(running_compiled_code=True)\n",
            "  File \"/anaconda/envs/azureml_py36/lib/python3.6/site-packages/IPython/core/interactiveshell.py\", line 2047, in showtraceback\n",
            "    value, tb, tb_offset=tb_offset)\n",
            "  File \"/anaconda/envs/azureml_py36/lib/python3.6/site-packages/IPython/core/ultratb.py\", line 1436, in structured_traceback\n",
            "    self, etype, value, tb, tb_offset, number_of_lines_of_context)\n",
            "  File \"/anaconda/envs/azureml_py36/lib/python3.6/site-packages/IPython/core/ultratb.py\", line 1336, in structured_traceback\n",
            "    self, etype, value, tb, tb_offset, number_of_lines_of_context\n",
            "  File \"/anaconda/envs/azureml_py36/lib/python3.6/site-packages/IPython/core/ultratb.py\", line 1193, in structured_traceback\n",
            "    tb_offset)\n",
            "  File \"/anaconda/envs/azureml_py36/lib/python3.6/site-packages/IPython/core/ultratb.py\", line 1150, in format_exception_as_a_whole\n",
            "    last_unique, recursion_repeat = find_recursion(orig_etype, evalue, records)\n",
            "  File \"/anaconda/envs/azureml_py36/lib/python3.6/site-packages/IPython/core/ultratb.py\", line 451, in find_recursion\n",
            "    return len(records), 0\n",
            "TypeError: object of type 'NoneType' has no len()\n",
            "\n",
            "During handling of the above exception, another exception occurred:\n",
            "\n",
            "Traceback (most recent call last):\n",
            "  File \"/anaconda/envs/azureml_py36/lib/python3.6/site-packages/IPython/core/interactiveshell.py\", line 2044, in showtraceback\n",
            "    stb = value._render_traceback_()\n",
            "AttributeError: 'TypeError' object has no attribute '_render_traceback_'\n",
            "\n",
            "During handling of the above exception, another exception occurred:\n",
            "\n",
            "Traceback (most recent call last):\n",
            "  File \"/anaconda/envs/azureml_py36/lib/python3.6/site-packages/IPython/core/interactiveshell.py\", line 2895, in _run_cell\n",
            "    return runner(coro)\n",
            "  File \"/anaconda/envs/azureml_py36/lib/python3.6/site-packages/IPython/core/async_helpers.py\", line 68, in _pseudo_sync_runner\n",
            "    coro.send(None)\n",
            "  File \"/anaconda/envs/azureml_py36/lib/python3.6/site-packages/IPython/core/interactiveshell.py\", line 3072, in run_cell_async\n",
            "    interactivity=interactivity, compiler=compiler, result=result)\n",
            "  File \"/anaconda/envs/azureml_py36/lib/python3.6/site-packages/IPython/core/interactiveshell.py\", line 3282, in run_ast_nodes\n",
            "    self.showtraceback()\n",
            "  File \"/anaconda/envs/azureml_py36/lib/python3.6/site-packages/IPython/core/interactiveshell.py\", line 2047, in showtraceback\n",
            "    value, tb, tb_offset=tb_offset)\n",
            "  File \"/anaconda/envs/azureml_py36/lib/python3.6/site-packages/IPython/core/ultratb.py\", line 1436, in structured_traceback\n",
            "    self, etype, value, tb, tb_offset, number_of_lines_of_context)\n",
            "  File \"/anaconda/envs/azureml_py36/lib/python3.6/site-packages/IPython/core/ultratb.py\", line 1336, in structured_traceback\n",
            "    self, etype, value, tb, tb_offset, number_of_lines_of_context\n",
            "  File \"/anaconda/envs/azureml_py36/lib/python3.6/site-packages/IPython/core/ultratb.py\", line 1211, in structured_traceback\n",
            "    chained_exceptions_tb_offset)\n",
            "  File \"/anaconda/envs/azureml_py36/lib/python3.6/site-packages/IPython/core/ultratb.py\", line 1150, in format_exception_as_a_whole\n",
            "    last_unique, recursion_repeat = find_recursion(orig_etype, evalue, records)\n",
            "  File \"/anaconda/envs/azureml_py36/lib/python3.6/site-packages/IPython/core/ultratb.py\", line 451, in find_recursion\n",
            "    return len(records), 0\n",
            "TypeError: object of type 'NoneType' has no len()\n",
            "\n",
            "During handling of the above exception, another exception occurred:\n",
            "\n",
            "Traceback (most recent call last):\n",
            "  File \"/anaconda/envs/azureml_py36/lib/python3.6/site-packages/IPython/core/interactiveshell.py\", line 2044, in showtraceback\n",
            "    stb = value._render_traceback_()\n",
            "AttributeError: 'TypeError' object has no attribute '_render_traceback_'\n",
            "\n",
            "During handling of the above exception, another exception occurred:\n",
            "\n",
            "Traceback (most recent call last):\n",
            "  File \"/anaconda/envs/azureml_py36/lib/python3.6/site-packages/IPython/core/ultratb.py\", line 1169, in get_records\n",
            "    return _fixed_getinnerframes(etb, number_of_lines_of_context, tb_offset)\n",
            "  File \"/anaconda/envs/azureml_py36/lib/python3.6/site-packages/IPython/core/ultratb.py\", line 316, in wrapped\n",
            "    return f(*args, **kwargs)\n",
            "  File \"/anaconda/envs/azureml_py36/lib/python3.6/site-packages/IPython/core/ultratb.py\", line 350, in _fixed_getinnerframes\n",
            "    records = fix_frame_records_filenames(inspect.getinnerframes(etb, context))\n",
            "  File \"/anaconda/envs/azureml_py36/lib/python3.6/inspect.py\", line 1490, in getinnerframes\n",
            "    frameinfo = (tb.tb_frame,) + getframeinfo(tb, context)\n",
            "  File \"/anaconda/envs/azureml_py36/lib/python3.6/inspect.py\", line 1448, in getframeinfo\n",
            "    filename = getsourcefile(frame) or getfile(frame)\n",
            "  File \"/anaconda/envs/azureml_py36/lib/python3.6/inspect.py\", line 696, in getsourcefile\n",
            "    if getattr(getmodule(object, filename), '__loader__', None) is not None:\n",
            "  File \"/anaconda/envs/azureml_py36/lib/python3.6/inspect.py\", line 725, in getmodule\n",
            "    file = getabsfile(object, _filename)\n",
            "  File \"/anaconda/envs/azureml_py36/lib/python3.6/inspect.py\", line 709, in getabsfile\n",
            "    return os.path.normcase(os.path.abspath(_filename))\n",
            "  File \"/anaconda/envs/azureml_py36/lib/python3.6/posixpath.py\", line 383, in abspath\n",
            "    cwd = os.getcwd()\n",
            "FileNotFoundError: [Errno 2] No such file or directory\n"
          ]
        }
      ],
      "execution_count": 4,
      "metadata": {
        "gather": {
          "logged": 1623578676268
        }
      }
    },
    {
      "cell_type": "markdown",
      "source": [
        "## View Azure Machine Learning resources in the workspace\n",
        "\n",
        "Now that you have a connection to your workspace, you can work with the resources. For example, you can use the following code to enumerate the compute resources in your workspace."
      ],
      "metadata": {}
    },
    {
      "cell_type": "code",
      "source": [
        "print(\"Compute Resources:\")\n",
        "for compute_name in ws.compute_targets:\n",
        "    compute = ws.compute_targets[compute_name]\n",
        "    print(\"\\t\", compute.name, ':', compute.type)"
      ],
      "outputs": [],
      "execution_count": null,
      "metadata": {}
    },
    {
      "cell_type": "markdown",
      "source": [
        "When you've finished exploring this notebook, you can save any changes you have made and close it."
      ],
      "metadata": {}
    }
  ],
  "metadata": {
    "kernelspec": {
      "name": "python3",
      "language": "python",
      "display_name": "Python 3"
    },
    "language_info": {
      "name": "python",
      "version": "3.6.9",
      "mimetype": "text/x-python",
      "codemirror_mode": {
        "name": "ipython",
        "version": 3
      },
      "pygments_lexer": "ipython3",
      "nbconvert_exporter": "python",
      "file_extension": ".py"
    },
    "kernel_info": {
      "name": "python3"
    },
    "nteract": {
      "version": "nteract-front-end@1.0.0"
    }
  },
  "nbformat": 4,
  "nbformat_minor": 4
}